Traceback (most recent call last):
  File "/usr/local/lib/python3.7/dist-packages/pandas/core/indexes/base.py", line 3080, in get_loc
    return self._engine.get_loc(casted_key)
  File "pandas/_libs/index.pyx", line 70, in pandas._libs.index.IndexEngine.get_loc
  File "pandas/_libs/index.pyx", line 101, in pandas._libs.index.IndexEngine.get_loc
  File "pandas/_libs/hashtable_class_helper.pxi", line 4554, in pandas._libs.hashtable.PyObjectHashTable.get_item
  File "pandas/_libs/hashtable_class_helper.pxi", line 4562, in pandas._libs.hashtable.PyObjectHashTable.get_item
KeyError: 'fan'

The above exception was the direct cause of the following exception:

Traceback (most recent call last):
  File "app.py", line 226, in main
    result = filterClassifier.predict()
  File "/home/pi/Desktop/IC-Air/FilterDetector/FilterDetector.py", line 64, in predict
    data = create_feature_vector([data])
  File "/home/pi/Desktop/IC-Air/FilterDetector/FilterDetector.py", line 28, in create_feature_vector
    avg_fan = df["fan"].mean()
  File "/usr/local/lib/python3.7/dist-packages/pandas/core/frame.py", line 3024, in __getitem__
    indexer = self.columns.get_loc(key)
  File "/usr/local/lib/python3.7/dist-packages/pandas/core/indexes/base.py", line 3082, in get_loc
    raise KeyError(key) from err
KeyError: 'fan'
